Workbook

Sheet Шари мапи
A1: NOMAD CLUB NETWORK — Шари інтерактивної карти + Відкриті джерела даних
A2: # | B2: Категорія шару | C2: Параметр / Показник | D2: Джерело даних | E2: API / URL | F2: Тип доступу | G2: Оновлення | H2: Пріоритет MVP
A3: 1 | B3: 🛡 БЕЗПЕКА | C3: Глобальний індекс миру | D3: Vision of Humanity / IEP | E3: visionofhumanity.org/gpi | F3: Free CSV | G3: Щорічно | H3: 🔴 MUST
A4: 2 | B4: 🛡 БЕЗПЕКА | C4: Рівень злочинності (Crime Index) | D4: Numbeo | E4: numbeo.com/api | F4: Free/Paid API | G4: Квартально | H4: 🔴 MUST
A5: 3 | B5: 🛡 БЕЗПЕКА | C5: Корупція (CPI) | D5: Transparency International | E5: transparency.org / data.worldbank.org | F5: Free JSON/CSV | G5: Щорічно | H5: 🔴 MUST
A6: 4 | B6: 🛡 БЕЗПЕКА | C6: Активні конфлікти / зони воєн | D6: ACLED / UCDP | E6: acleddata.com/api | ucdp.uu.se/api | F6: Free API | G6: Щотижня | H6: 🔴 MUST
A7: 5 | B7: 🛡 БЕЗПЕКА | C7: Попередження для мандрівників | D7: USA/UK/AU Governments | E7: travel.state.gov | smartraveller.gov.au | F7: RSS/JSON | G7: Реальний час | H7: 🔴 MUST
A8: 6 | B8: 🌍 КЛІМАТ | C8: Ризик стихійних лих | D8: UNDRR / EM-DAT | E8: emdat.be | data.undrr.org | F8: Free CSV/API | G8: Щорічно | H8: 🔴 MUST
A9: 7 | B9: 🌍 КЛІМАТ | C9: Якість повітря (AQI) | D9: OpenAQ / IQAir | E9: api.openaq.org | api.airvisual.com | F9: Free API | G9: Реальний час | H9: 🟡 HIGH
A10: 8 | B10: 🌍 КЛІМАТ | C10: Кліматичні зони та сезонність | D10: NASA POWER / Open-Meteo | E10: power.larc.nasa.gov/api | api.open-meteo.com | F10: Free API | G10: Реальний час | H10: 🟡 HIGH
A11: 9 | B11: 🌍 КЛІМАТ | C11: Ризик цунамі / землетрусів | D11: USGS / NOAA | E11: earthquake.usgs.gov/fdsnws | tsunami.noaa.gov | F11: Free JSON | G11: Реальний час | H11: 🟡 HIGH
A12: 10 | B12: 🌍 КЛІМАТ | C12: Якість питної води | D12: WHO / EPI Yale | E12: epi.yale.edu | data.who.int | F12: Free CSV | G12: Щорічно | H12: 🟢 NICE
A13: 11 | B13: ⚡ ІНФРАСТРУКТУРА | C13: Швидкість інтернету (Mbps) | D13: Speedtest / Ookla | E13: opendata.ookla.com | F13: Free шейп-файли | G13: Квартально | H13: 🔴 MUST
A14: 12 | B14: ⚡ ІНФРАСТРУКТУРА | C14: Покриття 5G/4G | D14: OpenCelliD / GSMA | E14: opencellid.org | gsma.com/intelligence | F14: Free API | G14: Щомісяця | H14: 🟡 HIGH
... A58: 48 | B58: 🔮 УНІКАЛЬНІ | C58: Indeks задоволеності жителів | D58: Gallup / Eurobarometer | E58: gallup.com/analytics | ec.europa.eu/eurostat/api | F58: Free/Paid | G58: Щорічно | H58: 🟢 NICE
A59: ЛЕГЕНДА: 🔴 MUST = обов'язково в MVP | 🟡 HIGH = другий пріоритет | 🟢 NICE = пізніше | РАЗОМ: 48 шарів

Sheet Фінмодель — BA Viamonte 1400
A1: ФІНАНСОВА МОДЕЛЬ — Viamonte 1400, San Nicolás, Buenos Aires
A2: 🔵 Сині = параметри (змінюй) | ⚫ Чорні = формули | 🟢 Зелені = результати | ⚠️ Жовті = ризики
A4: 1. ПРИДБАННЯ ($)
A5: Ціна об'єкту ($) | B5: 1300000
A6: Площа об'єкту (м²) | B6: 1416 | C6: 1,416 м² покритих
A7: Ціна $/м² (розрахунок) | B7: =B5/B6 -> 918.0791 | C7: ⬅ нижче ринку $1,500-2,500/м²
A8: Податки + нотаріус (%) | B8: 0.04
A9: Комісія агента (%) | B9: 0.03
A10: Legal / SPV структура ($) | B10: 40000 | C10: Іноземна власність AR
A11: TOTAL ПРИДБАННЯ | B11: =B5*(1+B8+B9)+B10 -> 1431000
A12: 2. РЕНОВАЦІЯ ($)
A13: Площа реновації (м²) | B13: 1050 | C13: Без 1-го поверху (кафе)
A14: Ціна реновації $/м² | B14: 1000 | C14: Оцінка партнера в BA
A15: Буфер несподіваний (%) | B15: 0.15 | C15: 81 рік будівлі!
A16: TOTAL РЕНОВАЦІЯ | B16: =B13*B14*(1+B15) -> 1207500 | C16: ⚠️ Ризик +20-50% для 81-річної будівлі
A17: 3. ЗАГАЛЬНИЙ ВХІД ($)
A18: 💰 TOTAL IN (повна вартість) | B18: =B11+B16 -> 2638500
A19: 4. ДОХОДИ ($/рік)
A20: Кількість юнітів (номерів) | B20: 24 | C20: Приблизна кількість
A21: Середня ставка за ніч ($) | B21: 150 | C21: Boutique, Teatro Colón
A22: Заповнюваність (%) | B22: 0.7 | C22: Реалістична 70%
A23: Днів у році | B23: 365
A24: Готельний дохід (рік) | B24: =B20*B21*B22*B23 -> 919800
A25: Оренда 1-го пов. комерційний ($/міс) | B25: 2500 | C25: Кафе/коворкінг
A26: Комерційний дохід (рік) | B26: =B25*12 -> 30000
A27: TOTAL ДОХІД (рік) | B27: =B24+B26 -> 949800
A28: 5. ОПЕРАЦІЙНІ ВИТРАТИ ($/рік)
A29: Локальний Персонал зарплати | B29: 100000 | C29: Прибирання, рецепція, управління
A30: Комунальні + обслуговування | B30: 40000
A31: Страхування + юридична підтримка | B31: 20000
A32: Маркетинг + OTA комісії (%) | B32: 0.1 | C32: 10% від доходу
A33: Management fee платформи (%) | B33: 0.05 | C33: 5% Nomad Club Network fee
A34: TOTAL ВИТРАТИ (рік) | B34: =B29+B30+B31+B27*B32+B27*B33 -> 302470
A35: 6. ПРИБУТКОВІСТЬ
A36: ДОХІД (NOI) | B36: =B27-B34 -> 647330
A37: ROI на вкладений капітал (%) | B37: =B36/B18 -> 0.24534016
A38: Термін повернення (роки) | B38: =IF(B36>0,B18/B36,0) -> 4.0759736
A40: 7. КЛУБНА СТРУКТУРА СПІВВЛАСНИКІВ
A41: Варіанти для 24 слотів | B41: Кількість власників | C41: Частка в слоті та періоді використання | D41: Вклад в частку слоту($) | E41: Дохід/особу ($/рік) | F41: Період окупності | G41: Цінність 90 дн. ($/рік) | H41: Business income ($/рік) | I41: Live & Business income
A42: A | B42: 18 | C42: 1 | D42: =B18/B42 -> 146583.33 | E42: =B36/B42 -> 35962.778 | F42: =D42/E42 -> 4.0759736 | G42: =B21*90 -> 13500 | H42: =B36/B42+B21*90 -> 49462.778 | I42: =B36/B42-B21*90 -> 22462.778
...

Sheet MVP Валідація
A1: ПЛАН ВАЛІДАЦІЇ — ВІД ТЕСТУ ВІРУСНОСТІ ДО ПЕРШОГО ОБ'ЄКТУ
A2: Фаза | B2: Що робимо | C2: Метрика успіху | D2: Бюджет | F2: Статус
A3: ФАЗА 0 А Тиждень 1 $0 | B3: Питання в 5 Telegram знакомих комьюнити, або nomad-групах: Чи уявляєте де може бути ваше ідельне місце для життя? Ідеальною була б земна куля, яка крутиться і на фоні якої зявлється питання на англ. французьскій, італьянскій, испанській, японській, корейскій, український, польскій, німецкій, індійскій, португальскій. 'Давай знайдемо його за параметраи на той мові на яку людина клікнула, за параметрами, останній рядок в позитивних та негативних параметрів - запропонуй чого нема?' МАПА з туманом (туман над територіями - країнами - регіонами, не над піном локації) и параметрами, як позитивними так і негативними, мінімально необхідними слоями, включено 5-6 слоями що повинні бути, після обирання параметру туман розходиться обо сходиться над тими місцями у світі де обрані параметри виконуються, наступний сходження/розходження туману це там де виконується і першій і другий і так до кінця параметрів. КНОПКи зберегти вибір - реєстрація / поділись з друзями - реєстрація / переивитися у кого є такий же ж вібір - реєстрація. Якщо нікого нема на мапі і у будь якому випадку сбоїв писати що це тестовая версія можливі збої ми повідомимо як тільки полагодимо, або як тільки люди зявляться - повідомити? так /ні - Повідомлення про те що зявився новий шар мапи і додавати раз в два дні | C3: ✅ 60%+ переслали мапу 'так' (Viral K-Factor > 0.2) | D3: 2000 | E3: Design (15h*$40) + Dev (20h*$50) + PM/QA=$400 | F3: 0
A4: ФАЗА 0B Тиждень 2 $0 | B4: Тест сторінок комьюніті з обєктами емульовані: - повідомлення зареєстрованим та нова хвиля з отривом в 24 години, після повідомлення по незнайомим - зявилася внутрішня сторінка комьюніті, зайди протестуй включаємо 7-13 емульованих сторінок з лістінгу преферентних. Послати в 3-5 знакомих комьюнити, або профільні nomad чати. МАР все те ж саме, тільки є комьюніті в різних стадіях: без обєкту, ленд, реновація, будівницство інші місця що залишаються без туману (туман над територіями - країнами - регіонами, не над піном локації) - повідомлення що зявилася нове комьюніті, напрям, локація, | C4: ❌ <40% = змінюємо подачу | D4: 800 | E4: Ads ($600) + Content (5h*$40)=$200 | F4: ⏳ через годину після реєстрації кожному. Друга волна через день після того як іссякне потік перших, якщо не іссякне то підключення іншіх чатів, груп в фб, інсте
A5: ФАЗА 0С Тиждень 3 $0 - 500 | B5: Test створення свого комьюніті - постав свій пін де бажаєш? якщо буде твоя ласка напиши чому саме тут? - наповни ідеологією - запроси іншіх до твого комьюніті - ідеальні сусіди на кочевому шлояху. - створи пін комьюніті - створи пін плейса конретного а навколо нього комьюніті власників - чи бажаєш знати якщо хтось ще зробить такий вибір / поділись своїм вибором з друзями - реєстрація. | C5: ЗАПИСАТИ - всі відповіді повинні складатися та фіксуватися у додатку | D5: 500 | E5: Тест створення ком'юніті (Dev 10h*$50)
A6: ФАЗА 0D Тиждень 4 $0 | B6: ТЕСТ існуючого комьюніті з реальним обїектом - БА, яка серед іншіх емуляцій має пульсацію до прикладу. БА ЛОКАЦІЯ на внутрішній сторінці - можливо калькулювати свою частку, - можливо додавати кредит, - пропонувати свою ціну - скільки б ти був би готовий сплатити? в яких пропорціях це стає цікавим для тебе? | C6: ✅ 50 пересилань ✅ 10+ LOI (LOI Conversion > 5%) | D6: 300 | E6: Тест БА (Dev 6h*$50)
A7: ФАЗА 1 Місяць 1-2 $500 - 1000 | B7: Typeform квест 10 питань → 'твій тип кочівника' - яке твоє комьюніті, → кнопка 'знайти схожих' - додати локацію, - створити комьюніті на напрямку → Telegram-група або чат бот відповідного типу що до сервісу та для конкретного місця - пін BA як першу точку та додати повідомлення всім хто зареєструвався про те: - які напрями обирають, - що вже можливо прям створювати свої комьюніті, - що на будь яких напрямах і виставляти обєкти, - про загальну чисельність тих хто зареєструвався, - про появу тих хто зробив такий же ж вибір, - повідомлення тим у кого багато співпадінь - зроби схожих "своїми", про те що можливо додавати людей до свого комюніті. | C7: ❌ <5 = переглядаємо цільову аудиторію та офер | D7: 1000 | E7: Typeform (5h*$40) + Ads ($800) | F7: 📋 ПІСЛЯ ФАЗА 0
A8: ФАЗА 1B Місяць 1-3 $200-500 | B8: Due diligence BA Viamonte: 1. Кафе — орендар чи власник? сповіщення 2. Зонування C2 → hospitality? сповіщення про реальну кількість слотів 3. Технічна документація? сповіщення про обсяги витрат на реновацію та період + Аргентинський юрист ($200-300) сповіщення з юридичним висновком та порядком реєстрацій та проведення платежів. Якщо ніхто до того часу не сплатив ніякого донейшену який повинен бути як на центральній сторінці, так і на сторінці конкретного обєкту - предметно за кроками, якщо ніхто то повідомлення про дії та пропозицію накинути по 5 баксів на формалізацію та дослідження за для таких цілей на кріптобанку. | C8: ✅ Юрист підтвердив структуру та 10+ донейтів на DD ($5) | D8: 1500 | E8: Legal Audit (8h*$150) + Translation/Notary=$300 | F8: 500
A9: ФАЗА 2 Місяць 3-6 $3-8k | B9: Мапа стає повністю інтерактивною з реєстраціями, проставленими пінами бажань, піном БА виконань, а може ще щось хтось підкине точку. інтерактивна карта: • всі шари підкоючені (безпека, COL, nomad visa, і т інше..) • Всіф функціональні кнопки працюють що до створення комьюніті, пінів, нанесення обєктів, створення тематиччних напрямків - оптувальники, кожна дія підіймає рейтінг активності конкретного чоловіка • об'єкт на карті — BA Viamonte та те що випливе | C9: ✅ 1000+ унікальних відвідувань та 100+ реєстрацій | D9: 12000 | E9: API Integ (60h*$60) + Back (60h*$60) + Front (60h*$50) + DevOps=$1800 | F9: 0
A10: ФАЗА 3 Місяць 5-12 $25-50k | B10: Підключення P2P та леджера блокчейну. Запуск Перший інвестиційний пул BA: • 10-15 учасників з підтвердженим бюджетом • SPV в Аргентині • створення бюджету реновації • Перший об'єкт Nomad Club Network - сповіщення про робочий апліфкейшн і сервіси - сповіщення про почаковий потік заінтересанів та ресурсів - про підключення банку - срахової кампанії, - опитування стосовно назви мережі готелів (urban&jungle) - встановлення камер на обєкті | C10: ✅ Total In = конкретне число | D10: 50000 | E10: Smart Contracts ($20k) + Bank/SPV ($15k) + Security Audit ($15k) | F10: 000) + Bank/SPV ($15 | G10: 000) + Security Audit ($15 | H10: 000) | Разом: $50 | I10: 0
A11: ФАЗА 4 | B11: Масштабування: | C11: ✅ 20+ активних користувачів (Stickiness > 20%) | D11: =SUM(D3:D10) -> 68100
D12: =SUM(D3:D10) -> 68100
A13: Місяць 12-24 | B13: • 20+ активних проектів | D13: =SUM(D2:D10) -> 68100
A14: $25-50k | B14: • Повноцінна робота DAO та банківських сервісів
B15: • Запуск мережі готелів (Urban & Jungle)
A17: МЕТРИКИ УСПІХУ MVP (Кількісні)
A18: Метрика | B18: Опис / Формула | C18: Цільовий показник
A19: Viral K-Factor | B19: Кількість нових користувачів від одного активного | C19: > 0.2
A20: LOI Conversion | B20: Конверсія у підписаний Letter of Intent (LOI) | C20: > 5%
A21: CAC | B21: Вартість залучення одного ліда | C21: < $50
A22: Stickiness | B22: Співвідношення DAU/MAU | C22: > 20%
A23: Retention (D30) | B23: Відсоток повернення через місяць | C23: > 15%
A25: МЕТРИКИ УСПІХУ MVP (Якісні)
A26: Метрика | B26: Метод вимірювання | C26: Цільовий показник
A27: PMF Score | B27: Опитування: "Як би ви почувалися...?" | C27: > 40% "Дуже засмучений"
A28: NPS | B28: Net Promoter Score | C28: > 50
A29: Time to Value | B29: Час до першої корисної дії | C29: < 5 хв

Sheet Діаграма 1 Розподіл бюджету за 
A3: Phase | B3: Budget
A4: Phase 0A | B4: ='MVP Валідація'!D3 -> 2000
A5: Phase 0B | B5: ='MVP Валідація'!D4 -> 800
A6: Phase 0C | B6: ='MVP Валідація'!D5 -> 500
A7: Phase 0D | B7: ='MVP Валідація'!D6 -> 300
A8: Phase 1 | B8: ='MVP Валідація'!D7 -> 1000
A9: Phase 1B | B9: ='MVP Валідація'!D8 -> 1500
A10: Phase 2 | B10: ='MVP Валідація'!D9 -> 12000
A11: Phase 3 | B11: ='MVP Валідація'!D10 -> 50000
A12: Phase 4 | B12: ='MVP Валідація'!D11 -> 68100
